[2025-05-22 18:15:57] Starting stage: Frame Extraction
[2025-05-22 18:15:57] ✓ Frame Extraction completed successfully
[2025-05-22 18:15:57] Starting stage: GCS Sync
[2025-05-22 18:15:59] ✓ GCS Sync completed successfully
[2025-05-22 18:15:59] Starting stage: Label Studio Sync
[2025-05-22 18:16:01] ✗ Label Studio Sync failed: Traceback (most recent call last):
  File "/Users/malikmacbook/Desktop/pipeline/.venv/lib/python3.13/site-packages/urllib3/connection.py", line 198, in _new_conn
    sock = connection.create_connection(
        (self._dns_host, self.port),
    ...<2 lines>...
        socket_options=self.socket_options,
    )
  File "/Users/malikmacbook/Desktop/pipeline/.venv/lib/python3.13/site-packages/urllib3/util/connection.py", line 85, in create_connection
    raise err
  File "/Users/malikmacbook/Desktop/pipeline/.venv/lib/python3.13/site-packages/urllib3/util/connection.py", line 73, in create_connection
    sock.connect(sa)
    ~~~~~~~~~~~~^^^^
ConnectionRefusedError: [Errno 61] Connection refused

The above exception was the direct cause of the following exception:

Traceback (most recent call last):
  File "/Users/malikmacbook/Desktop/pipeline/.venv/lib/python3.13/site-packages/urllib3/connectionpool.py", line 787, in urlopen
    response = self._make_request(
        conn,
    ...<10 lines>...
        **response_kw,
    )
  File "/Users/malikmacbook/Desktop/pipeline/.venv/lib/python3.13/site-packages/urllib3/connectionpool.py", line 493, in _make_request
    conn.request(
    ~~~~~~~~~~~~^
        method,
        ^^^^^^^
    ...<6 lines>...
        enforce_content_length=enforce_content_length,
        ^^^^^^^^^^^^^^^^^^^^^^^^^^^^^^^^^^^^^^^^^^^^^^
    )
    ^
  File "/Users/malikmacbook/Desktop/pipeline/.venv/lib/python3.13/site-packages/urllib3/connection.py", line 445, in request
    self.endheaders()
    ~~~~~~~~~~~~~~~^^
  File "/opt/homebrew/Cellar/python@3.13/3.13.3/Frameworks/Python.framework/Versions/3.13/lib/python3.13/http/client.py", line 1333, in endheaders
    self._send_output(message_body, encode_chunked=encode_chunked)
    ~~~~~~~~~~~~~~~~~^^^^^^^^^^^^^^^^^^^^^^^^^^^^^^^^^^^^^^^^^^^^^
  File "/opt/homebrew/Cellar/python@3.13/3.13.3/Frameworks/Python.framework/Versions/3.13/lib/python3.13/http/client.py", line 1093, in _send_output
    self.send(msg)
    ~~~~~~~~~^^^^^
  File "/opt/homebrew/Cellar/python@3.13/3.13.3/Frameworks/Python.framework/Versions/3.13/lib/python3.13/http/client.py", line 1037, in send
    self.connect()
    ~~~~~~~~~~~~^^
  File "/Users/malikmacbook/Desktop/pipeline/.venv/lib/python3.13/site-packages/urllib3/connection.py", line 276, in connect
    self.sock = self._new_conn()
                ~~~~~~~~~~~~~~^^
  File "/Users/malikmacbook/Desktop/pipeline/.venv/lib/python3.13/site-packages/urllib3/connection.py", line 213, in _new_conn
    raise NewConnectionError(
        self, f"Failed to establish a new connection: {e}"
    ) from e
urllib3.exceptions.NewConnectionError: <urllib3.connection.HTTPConnection object at 0x10bc34180>: Failed to establish a new connection: [Errno 61] Connection refused

The above exception was the direct cause of the following exception:

Traceback (most recent call last):
  File "/Users/malikmacbook/Desktop/pipeline/.venv/lib/python3.13/site-packages/requests/adapters.py", line 667, in send
    resp = conn.urlopen(
        method=request.method,
    ...<9 lines>...
        chunked=chunked,
    )
  File "/Users/malikmacbook/Desktop/pipeline/.venv/lib/python3.13/site-packages/urllib3/connectionpool.py", line 871, in urlopen
    return self.urlopen(
           ~~~~~~~~~~~~^
        method,
        ^^^^^^^
    ...<13 lines>...
        **response_kw,
        ^^^^^^^^^^^^^^
    )
    ^
  File "/Users/malikmacbook/Desktop/pipeline/.venv/lib/python3.13/site-packages/urllib3/connectionpool.py", line 871, in urlopen
    return self.urlopen(
           ~~~~~~~~~~~~^
        method,
        ^^^^^^^
    ...<13 lines>...
        **response_kw,
        ^^^^^^^^^^^^^^
    )
    ^
  File "/Users/malikmacbook/Desktop/pipeline/.venv/lib/python3.13/site-packages/urllib3/connectionpool.py", line 871, in urlopen
    return self.urlopen(
           ~~~~~~~~~~~~^
        method,
        ^^^^^^^
    ...<13 lines>...
        **response_kw,
        ^^^^^^^^^^^^^^
    )
    ^
  File "/Users/malikmacbook/Desktop/pipeline/.venv/lib/python3.13/site-packages/urllib3/connectionpool.py", line 841, in urlopen
    retries = retries.increment(
        method, url, error=new_e, _pool=self, _stacktrace=sys.exc_info()[2]
    )
  File "/Users/malikmacbook/Desktop/pipeline/.venv/lib/python3.13/site-packages/urllib3/util/retry.py", line 519, in increment
    raise MaxRetryError(_pool, url, reason) from reason  # type: ignore[arg-type]
    ^^^^^^^^^^^^^^^^^^^^^^^^^^^^^^^^^^^^^^^^^^^^^^^^^^^
urllib3.exceptions.MaxRetryError: HTTPConnectionPool(host='localhost', port=8080): Max retries exceeded with url: /api/version (Caused by NewConnectionError('<urllib3.connection.HTTPConnection object at 0x10bc34180>: Failed to establish a new connection: [Errno 61] Connection refused'))

During handling of the above exception, another exception occurred:

Traceback (most recent call last):
  File "/Users/malikmacbook/Desktop/pipeline/scripts/labelstudio_sync.py", line 92, in <module>
    ls_sync = LabelStudioSync(config)
  File "/Users/malikmacbook/Desktop/pipeline/scripts/labelstudio_sync.py", line 10, in __init__
    self.ls = Client(
              ~~~~~~^
        url=config['labelstudio']['url'],
        ^^^^^^^^^^^^^^^^^^^^^^^^^^^^^^^^^
        api_key=config['labelstudio']['api_key']
        ^^^^^^^^^^^^^^^^^^^^^^^^^^^^^^^^^^^^^^^^
    )
    ^
  File "/Users/malikmacbook/Desktop/pipeline/.venv/lib/python3.13/site-packages/label_studio_sdk/_legacy/client.py", line 111, in __init__
    self.versions = versions if versions else self.get_versions()
                                              ~~~~~~~~~~~~~~~~~^^
  File "/Users/malikmacbook/Desktop/pipeline/.venv/lib/python3.13/site-packages/label_studio_sdk/_legacy/client.py", line 122, in get_versions
    self.versions = self.make_request("GET", "/api/version").json()
                    ~~~~~~~~~~~~~~~~~^^^^^^^^^^^^^^^^^^^^^^^
  File "/Users/malikmacbook/Desktop/pipeline/.venv/lib/python3.13/site-packages/label_studio_sdk/_legacy/client.py", line 436, in make_request
    response = self.session.request(
        method,
    ...<4 lines>...
        **kwargs,
    )
  File "/Users/malikmacbook/Desktop/pipeline/.venv/lib/python3.13/site-packages/requests/sessions.py", line 589, in request
    resp = self.send(prep, **send_kwargs)
  File "/Users/malikmacbook/Desktop/pipeline/.venv/lib/python3.13/site-packages/requests/sessions.py", line 703, in send
    r = adapter.send(request, **kwargs)
  File "/Users/malikmacbook/Desktop/pipeline/.venv/lib/python3.13/site-packages/requests/adapters.py", line 700, in send
    raise ConnectionError(e, request=request)
requests.exceptions.ConnectionError: HTTPConnectionPool(host='localhost', port=8080): Max retries exceeded with url: /api/version (Caused by NewConnectionError('<urllib3.connection.HTTPConnection object at 0x10bc34180>: Failed to establish a new connection: [Errno 61] Connection refused'))

[2025-05-22 18:16:01] Pipeline stopped due to error
